Workbook

Sheet Tracker&Invoice
A2: ITEM | B2: Description | C2: OLD QUANTITY | D2: C.R QUANTITY | E2: UNITE | F2: PRICE | G2: TOTAL | H2: 0.6 | I2: 0.3 | J2: 0.1
A4: D-001 | B4: التصاميم التفصيلية وتصاميم المرحلة الثالثة Stage 3 Design Package | C4: 1 | D4: 1 | E4: عدد | F4: 2840000 | G4: 2840000 | H4: Submittal 1 | I4: Submittal 2 | J4: HCIS Approval
B6: TRACKER #01 | H6: =1*60% -> 0.6
B7: INVOICE #01 | H7: =F4*H6 -> 1704000
B8: TRACKER #03 | I8: 0.3
B9: INVOICE #03 | I9: =F4*I8 -> 852000
B10: TRACKER #05 | J10: 0.1
B11: INVOICE #05 | J11: =F4*J10 -> 284000
B12: Overall Completion INVOICE | H12: =H7+I9+J11 -> 2840000
B13: Overall Completion | H13: =H12/G4 -> 1
A15: ITEM | B15: Description | C15: OLD QUANTITY | D15: C.R QUANTITY | E15: UNITE | F15: PRICE | G15: TOTAL | H15: 0.6 | J15: 0.4
A17: D-002 | B17: الهندسة والتصميم IFC, Shop drawings and Stage 4 drawings | C17: 1 | D17: 1 | E17: عدد | F17: 2630000 | G17: 2630000 | H17: Shop Drawings | J17: AS BUILT
H18: 0.8 | I18: 0.2
B19: TRACKER #05 | H19: 26.4
B20: INVOICE #05 | H20: =(H19/264)*G17*H15*H18 -> 126240
B21: TRACKER #06 | H21: 68
B22: INVOICE #06 | H22: =(H21/264)*F17*H15*H18 -> 325163.64
B23: TRACKER #07 | H23: 100
B24: INVOICE #07 | H24: =(H23/264)*F17*H15*H18 -> 478181.82
B25: TRACKER #08 | H25: 10
B26: INVOICE #08 | H26: =(H25/264)*F17*H15*H18 -> 47818.182
B27: TRACKER #10 | H27: 16
B28: INVOICE #10 | H28: =(H27/264)*F17*H15*H18 -> 76509.091
B29: TRACKER #11 | H29: 7
B30: INVOICE #11 | H30: =(H29/264)*F17*H15*H18 -> 33472.727
B31: TRACKER #12 | H31: 8
B32: INVOICE #12 | H32: =(H31/264)*F17*H15*H18 -> 38254.545
B33: TRACKER #14 | H33: 5.599998
B34: INVOICE #14 | H34: =(H33/264)*G17*H15*H18 -> 26778.172
B35: TRACKER #15 | H35: 18
B36: INVOICE #15 | H36: =(H35/264)*G17*H15*H18 -> 86072.727
B37: TRACKER #20 | H37: 5
B38: INVOICE #20 | H38: =(5/264)*G17*H15*H18 -> 23909.091
B39: TRACKER #26 | I39: 264
B40: INVOICE #26 | I40: =(264/264)*G17*H15*I18 -> 315600
B41: Overall Completion TRACKER | H41: =H19+H21+H23+H25+H27+H29+H31+H33+H35+H37 -> 264 | I41: =I39 -> 264
B42: Overall Completion INVOICE | H42: =H32+H30+H28+H26+H24+H22+H20+H34+H36+H38+0.01 -> 1262400 | I42: =I40 -> 315600
B43: ToT.Overall Completion INVOICE | H43: =H42+I42+J42 -> 1578000
B44: Overall Completion | H44: =H43/G17 -> 0.6
A46: ITEM | B46: Description | C46: OLD QUANTITY | D46: C.R QUANTITY | E46: UNITE | F46: PRICE | G46: TOTAL | H46: 0.9 | I46: 0.1
...

Sheet Summry Invoices
A1: رقم المستخلص | B1: الفترة | D1: السنة | E1: قيمة الأعمال المنجزة | F1: نسبة المستخلص من العقد | G1: النسبة التراكمية | H1: الأعمال التراكمية | I1: استقطاع الدفعة المقدمة | J1: احتجاز الختامي | K1: صافي المستخلص بعد الاستقطاعات | L1: حسومات أخرى | M1: بيان الحسومات | N1: غرامات التأخير | O1: غرامات الإشراف | P1: إجمالي الحسومات والغرامات | Q1: صافي المستحق | R1: المنصرف التراكمي
A2: Tot' | B2: From | C2: To | E2: =SUM(E3:E38) -> #REF! | F2: =IF([1]المدخلات!$B$5=0,0,E2/[1]المدخلات!$B$5) -> #REF! | G2: =F2 -> #REF! | H2: =E2 -> #REF! | I2: =SUM(I3:I38) -> #REF! | J2: =SUM(J3:J38) -> #REF! | K2: =SUM(K3:K38) -> #REF! | L2: =SUM(L3:L38) -> 210000 | N2: =SUM(N3:N38) -> #VALUE! | O2: =SUM(O3:O38) -> 698425.33 | P2: =SUM(P3:P38) -> #REF! | Q2: =SUM(Q3:Q38) -> #REF! | R2: =Q2 -> #REF!
A3: 1 | B3: 45025 | C3: 45169 | D3: 2023 | E3: ='Data Board'!B35 -> #REF! | F3: =IF($E3="","",E3/[1]المدخلات!$B$5) -> #REF! | G3: =IF($E3="","",SUM(E$3:E3)/[1]المدخلات!$B$5) -> #REF! | H3: =IF($E3="","",SUM(E$3:E3)) -> #REF! | I3: =IF($E3="","",E3*[1]المدخلات!$B$8) -> #REF! | J3: =IF($E3="","",E3*[1]المدخلات!$B$9) -> #REF! | K3: =IF($E3="","",E3-I3-J3) -> #REF! | L3: 119000 | M3: (عدم تواجد مدير المشروع 119 يوم عمل) | N3: 0 | O3: 0 | P3: =IF($E3="","",N(L3)+N3+O3) -> #REF! | Q3: =IF($E3="","",K3-P3) -> #REF! | R3: =IF($E3="","",SUM(Q$3:Q3)) -> #REF!
A4: 2 | B4: 45170 | C4: 45209 | D4: 2023 | E4: ='Data Board'!B36 -> #REF! | F4: =IF($E4="","",E4/[1]المدخلات!$B$5) -> #REF! | G4: =IF($E4="","",SUM(E$3:E4)/[1]المدخلات!$B$5) -> #REF! | H4: =IF($E4="","",SUM(E$3:E4)) -> #REF! | I4: =IF($E4="","",E4*[1]المدخلات!$B$8) -> #REF! | J4: =IF($E4="","",E4*[1]المدخلات!$B$9) -> #REF! | K4: =IF($E4="","",E4-I4-J4) -> #REF! | N4: 0 | O4: 0 | P4: =IF($E4="","",N(L4)+N4+O4) -> #REF! | Q4: =IF($E4="","",K4-P4) -> #REF! | R4: =IF($E4="","",SUM(Q$3:Q4)) -> #REF!
A5: 3 | B5: 45210 | C5: 45228 | D5: 2023 | E5: ='Data Board'!B37 -> #REF! | F5: =IF($E5="","",E5/[1]المدخلات!$B$5) -> #REF! | G5: =IF($E5="","",SUM(E$3:E5)/[1]المدخلات!$B$5) -> #REF! | H5: =IF($E5="","",SUM(E$3:E5)) -> #REF! | I5: =IF($E5="","",E5*[1]المدخلات!$B$8) -> #REF! | J5: =IF($E5="","",E5*[1]المدخلات!$B$9) -> #REF! | K5: =IF($E5="","",E5-I5-J5) -> #REF! | N5: 0 | O5: 0 | P5: =IF($E5="","",N(L5)+N5+O5) -> #REF! | Q5: =IF($E5="","",K5-P5) -> #REF! | R5: =IF($E5="","",SUM(Q$3:Q5)) -> #REF!
A6: 4 | B6: 46324 | C6: 45238 | D6: 2023 | E6: ='Data Board'!B38 -> #REF! | F6: =IF($E6="","",E6/[1]المدخلات!$B$5) -> #REF! | G6: =IF($E6="","",SUM(E$3:E6)/[1]المدخلات!$B$5) -> #REF! | H6: =IF($E6="","",SUM(E$3:E6)) -> #REF! | I6: =IF($E6="","",E6*[1]المدخلات!$B$8) -> #REF! | J6: =IF($E6="","",E6*[1]المدخلات!$B$9) -> #REF! | K6: =IF($E6="","",E6-I6-J6) -> #REF! | N6: 0 | O6: 0 | P6: =IF($E6="","",N(L6)+N6+O6) -> #REF! | Q6: =IF($E6="","",K6-P6) -> #REF! | R6: =IF($E6="","",SUM(Q$3:Q6)) -> #REF!
A7: 5 | B7: 45239 | C7: 45319 | D7: 2024 | E7: ='Data Board'!B39 -> #REF! | F7: =IF($E7="","",E7/[1]المدخلات!$B$5) -> #REF! | G7: =IF($E7="","",SUM(E$3:E7)/[1]المدخلات!$B$5) -> #REF! | H7: =IF($E7="","",SUM(E$3:E7)) -> #REF! | I7: =IF($E7="","",E7*[1]المدخلات!$B$8) -> #REF! | J7: =IF($E7="","",E7*[1]المدخلات!$B$9) -> #REF! | K7: =IF($E7="","",E7-I7-J7) -> #REF! | L7: 27000 | M7: (عدم تواجد المهندس المدني 45 يوم ) | N7: 0 | O7: 0 | P7: =IF($E7="","",N(L7)+N7+O7) -> #REF! | Q7: =IF($E7="","",K7-P7) -> #REF! | R7: =IF($E7="","",SUM(Q$3:Q7)) -> #REF!
A8: 6 | B8: 45319 | C8: 45347 | D8: 2024 | E8: ='Data Board'!B40 -> #REF! | F8: =IF($E8="","",E8/[1]المدخلات!$B$5) -> #REF! | G8: =IF($E8="","",SUM(E$3:E8)/[1]المدخلات!$B$5) -> #REF! | H8: =IF($E8="","",SUM(E$3:E8)) -> #REF! | I8: =IF($E8="","",E8*[1]المدخلات!$B$8) -> #REF! | J8: =IF($E8="","",E8*[1]المدخلات!$B$9) -> #REF! | K8: =IF($E8="","",E8-I8-J8) -> #REF! | N8: 0 | O8: 0 | P8: =IF($E8="","",N(L8)+N8+O8) -> #REF! | Q8: =IF($E8="","",K8-P8) -> #REF! | R8: =IF($E8="","",SUM(Q$3:Q8)) -> #REF!
A9: 7 | B9: 45411 | C9: 45379 | D9: 2024 | E9: ='Data Board'!B41 -> #REF! | F9: =IF($E9="","",E9/[1]المدخلات!$B$5) -> #REF! | G9: =IF($E9="","",SUM(E$3:E9)/[1]المدخلات!$B$5) -> #REF! | H9: =IF($E9="","",SUM(E$3:E9)) -> #REF! | I9: =IF($E9="","",E9*[1]المدخلات!$B$8) -> #REF! | J9: =IF($E9="","",E9*[1]المدخلات!$B$9) -> #REF! | K9: =IF($E9="","",E9-I9-J9) -> #REF! | N9: 0 | O9: 0 | P9: =IF($E9="","",N(L9)+N9+O9) -> #REF! | Q9: =IF($E9="","",K9-P9) -> #REF! | R9: =IF($E9="","",SUM(Q$3:Q9)) -> #REF!
A10: 8 | B10: 45359 | C10: 45411 | D10: 2024 | E10: ='Data Board'!B42 -> #REF! | F10: =IF($E10="","",E10/[1]المدخلات!$B$5) -> #REF! | G10: =IF($E10="","",SUM(E$3:E10)/[1]المدخلات!$B$5) -> #REF! | H10: =IF($E10="","",SUM(E$3:E10)) -> #REF! | I10: =IF($E10="","",E10*[1]المدخلات!$B$8) -> #REF! | J10: =IF($E10="","",E10*[1]المدخلات!$B$9) -> #REF! | K10: =IF($E10="","",E10-I10-J10) -> #REF! | N10: 0 | O10: 0 | P10: =IF($E10="","",N(L10)+N10+O10) -> #REF! | Q10: =IF($E10="","",K10-P10) -> #REF! | R10: =IF($E10="","",SUM(Q$3:Q10)) -> #REF!
A11: 9 | B11: April 30, 2024 | C11: May 22, 2024 | D11: 2024 | E11: ='Data Board'!B43 -> #REF! | F11: =IF($E11="","",E11/[1]المدخلات!$B$5) -> #REF! | G11: =IF($E11="","",SUM(E$3:E11)/[1]المدخلات!$B$5) -> #REF! | H11: =IF($E11="","",SUM(E$3:E11)) -> #REF! | I11: =IF($E11="","",E11*[1]المدخلات!$B$8) -> #REF! | J11: =IF($E11="","",E11*[1]المدخلات!$B$9) -> #REF! | K11: =IF($E11="","",E11-I11-J11) -> #REF! | N11: 0 | O11: 0 | P11: =IF($E11="","",N(L11)+N11+O11) -> #REF! | Q11: =IF($E11="","",K11-P11) -> #REF! | R11: =IF($E11="","",SUM(Q$3:Q11)) -> #REF!
A12: 10 | B12: June 11, 2024 | C12: July 29, 2024 | D12: 2024 | E12: ='Data Board'!B44 -> #REF! | F12: =IF($E12="","",E12/[1]المدخلات!$B$5) -> #REF! | G12: =IF($E12="","",SUM(E$3:E12)/[1]المدخلات!$B$5) -> #REF! | H12: =IF($E12="","",SUM(E$3:E12)) -> #REF! | I12: =IF($E12="","",E12*[1]المدخلات!$B$8) -> #REF! | J12: =IF($E12="","",E12*[1]المدخلات!$B$9) -> #REF! | K12: =IF($E12="","",E12-I12-J12) -> #REF! | N12: 0 | O12: 0 | P12: =IF($E12="","",N(L12)+N12+O12) -> #REF! | Q12: =IF($E12="","",K12-P12) -> #REF! | R12: =IF($E12="","",SUM(Q$3:Q12)) -> #REF!
A13: 11 | B13: May 23, 2024 | C13: June 10, 2024 | D13: 2024 | E13: ='Data Board'!$B$45 -> #REF! | F13: =IF($E13="","",E13/[1]المدخلات!$B$5) -> #REF! | G13: =IF($E13="","",SUM(E$3:E13)/[1]المدخلات!$B$5) -> #REF! | H13: =IF($E13="","",SUM(E$3:E13)) -> #REF! | I13: =IF($E13="","",E13*[1]المدخلات!$B$8) -> #REF! | J13: =IF($E13="","",E13*[1]المدخلات!$B$9) -> #REF! | K13: =IF($E13="","",E13-I13-J13) -> #REF! | N13: 0 | O13: 0 | P13: =IF($E13="","",N(L13)+N13+O13) -> #REF! | Q13: =IF($E13="","",K13-P13) -> #REF! | R13: =IF($E13="","",SUM(Q$3:Q13)) -> #REF!
A14: 12 | B14: July 30, 2024 | C14: August 28, 2024 | D14: 2024 | E14: ='Data Board'!B46 -> #REF! | F14: =IF($E14="","",E14/[1]المدخلات!$B$5) -> #REF! | G14: =IF($E14="","",SUM(E$3:E14)/[1]المدخلات!$B$5) -> #REF! | H14: =IF($E14="","",SUM(E$3:E14)) -> #REF! | I14: =IF($E14="","",E14*[1]المدخلات!$B$8) -> #REF! | J14: =IF($E14="","",E14*[1]المدخلات!$B$9) -> #REF! | K14: =IF($E14="","",E14-I14-J14) -> #REF! | N14: 0 | O14: 0 | P14: =IF($E14="","",N(L14)+N14+O14) -> #REF! | Q14: =IF($E14="","",K14-P14) -> #REF! | R14: =IF($E14="","",SUM(Q$3:Q14)) -> #REF!
A15: 13 | B15: August 29, 2024 | C15: September 29, 2024 | D15: 2024 | E15: ='Data Board'!B47 -> #REF! | F15: =IF($E15="","",E15/[1]المدخلات!$B$5) -> #REF! | G15: =IF($E15="","",SUM(E$3:E15)/[1]المدخلات!$B$5) -> #REF! | H15: =IF($E15="","",SUM(E$3:E15)) -> #REF! | I15: =IF($E15="","",E15*[1]المدخلات!$B$8) -> #REF! | J15: =IF($E15="","",E15*[1]المدخلات!$B$9) -> #REF! | K15: =IF($E15="","",E15-I15-J15) -> #REF! | N15: 0 | O15: 0 | P15: =IF($E15="","",N(L15)+N15+O15) -> #REF! | Q15: =IF($E15="","",K15-P15) -> #REF! | R15: =IF($E15="","",SUM(Q$3:Q15)) -> #REF!
A16: 14 | B16: September 30, 2024 | C16: October 28, 2024 | D16: 2024 | E16: ='Data Board'!B48 -> #REF! | F16: =IF($E16="","",E16/[1]المدخلات!$B$5) -> #REF! | G16: =IF($E16="","",SUM(E$3:E16)/[1]المدخلات!$B$5) -> #REF! | H16: =IF($E16="","",SUM(E$3:E16)) -> #REF! | I16: =IF($E16="","",E16*[1]المدخلات!$B$8) -> #REF! | J16: =IF($E16="","",E16*[1]المدخلات!$B$9) -> #REF! | K16: =IF($E16="","",E16-I16-J16) -> #REF! | N16: 0 | O16: 0 | P16: =IF($E16="","",N(L16)+N16+O16) -> #REF! | Q16: =IF($E16="","",K16-P16) -> #REF! | R16: =IF($E16="","",SUM(Q$3:Q16)) -> #REF!
A17: 15 | B17: October 29, 2024 | C17: November 19, 2024 | D17: 2024 | E17: ='Data Board'!B49 -> #REF! | F17: =IF($E17="","",E17/[1]المدخلات!$B$5) -> #REF! | G17: =IF($E17="","",SUM(E$3:E17)/[1]المدخلات!$B$5) -> #REF! | H17: =IF($E17="","",SUM(E$3:E17)) -> #REF! | I17: =IF($E17="","",E17*[1]المدخلات!$B$8) -> #REF! | J17: =IF($E17="","",E17*[1]المدخلات!$B$9) -> #REF! | K17: =IF($E17="","",E17-I17-J17) -> #REF! | N17: 0 | O17: 0 | P17: =IF($E17="","",N(L17)+N17+O17) -> #REF! | Q17: =IF($E17="","",K17-P17) -> #REF! | R17: =IF($E17="","",SUM(Q$3:Q17)) -> #REF!
A18: 16 | B18: November 20, 2024 | C18: December 31, 2024 | D18: 2024 | E18: ='Data Board'!B50 -> #REF! | F18: =IF($E18="","",E18/[1]المدخلات!$B$5) -> #REF! | G18: =IF($E18="","",SUM(E$3:E18)/[1]المدخلات!$B$5) -> #REF! | H18: =IF($E18="","",SUM(E$3:E18)) -> #REF! | I18: =IF($E18="","",E18*[1]المدخلات!$B$8) -> #REF! | J18: =IF($E18="","",E18*[1]المدخلات!$B$9) -> #REF! | K18: =IF($E18="","",E18-I18-J18) -> #REF! | N18: 0 | O18: 0 | P18: =IF($E18="","",N(L18)+N18+O18) -> #REF! | Q18: =IF($E18="","",K18-P18) -> #REF! | R18: =IF($E18="","",SUM(Q$3:Q18)) -> #REF!
A19: 17 | B19: January 1, 2025 | C19: February 25, 2025 | D19: 2025 | E19: ='Data Board'!B51 -> #REF! | F19: =IF($E19="","",E19/[1]المدخلات!$B$5) -> #REF! | G19: =IF($E19="","",SUM(E$3:E19)/[1]المدخلات!$B$5) -> #REF! | H19: =IF($E19="","",SUM(E$3:E19)) -> #REF! | I19: =IF($E19="","",E19*[1]المدخلات!$B$8) -> #REF! | J19: =IF($E19="","",E19*[1]المدخلات!$B$9) -> #REF! | K19: =IF($E19="","",E19-I19-J19) -> #REF! | N19: 0 | O19: 0 | P19: =IF($E19="","",N(L19)+N19+O19) -> #REF! | Q19: =IF($E19="","",K19-P19) -> #REF! | R19: =IF($E19="","",SUM(Q$3:Q19)) -> #REF!
A20: 18 | B20: February 26, 2025 | C20: March 23, 2025 | D20: 2025 | E20: ='Data Board'!B52 -> #REF! | F20: =IF($E20="","",E20/[1]المدخلات!$B$5) -> #REF! | G20: =IF($E20="","",SUM(E$3:E20)/[1]المدخلات!$B$5) -> #REF! | H20: =IF($E20="","",SUM(E$3:E20)) -> #REF! | I20: =IF($E20="","",E20*[1]المدخلات!$B$8) -> #REF! | J20: =IF($E20="","",E20*[1]المدخلات!$B$9) -> #REF! | K20: =IF($E20="","",E20-I20-J20) -> #REF! | N20: 0 | O20: 0 | P20: =IF($E20="","",N(L20)+N20+O20) -> #REF! | Q20: =IF($E20="","",K20-P20) -> #REF! | R20: =IF($E20="","",SUM(Q$3:Q20)) -> #REF!
A21: 19 | B21: March 24, 2025 | C21: April 28, 2025 | D21: 2025 | E21: ='Data Board'!B53 -> #REF! | F21: =IF($E21="","",E21/[1]المدخلات!$B$5) -> #REF! | G21: =IF($E21="","",SUM(E$3:E21)/[1]المدخلات!$B$5) -> #REF! | H21: =IF($E21="","",SUM(E$3:E21)) -> #REF! | I21: =IF($E21="","",E21*[1]المدخلات!$B$8) -> #REF! | J21: =IF($E21="","",E21*[1]المدخلات!$B$9) -> #REF! | K21: =IF($E21="","",E21-I21-J21) -> #REF! | N21: 0 | O21: 0 | P21: =IF($E21="","",N(L21)+N21+O21) -> #REF! | Q21: =IF($E21="","",K21-P21) -> #REF! | R21: =IF($E21="","",SUM(Q$3:Q21)) -> #REF!
A22: 20 | B22: April 29, 2025 | C22: May 25, 2025 | D22: 2025 | E22: ='Data Board'!B54 -> #REF! | F22: =IF($E22="","",E22/[1]المدخلات!$B$5) -> #REF! | G22: =IF($E22="","",SUM(E$3:E22)/[1]المدخلات!$B$5) -> #REF! | H22: =IF($E22="","",SUM(E$3:E22)) -> #REF! | I22: =IF($E22="","",E22*[1]المدخلات!$B$8) -> #REF! | J22: =IF($E22="","",E22*[1]المدخلات!$B$9) -> #REF! | K22: =IF($E22="","",E22-I22-J22) -> #REF! | N22: 0 | O22: 0 | P22: =IF($E22="","",N(L22)+N22+O22) -> #REF! | Q22: =IF($E22="","",K22-P22) -> #REF! | R22: =IF($E22="","",SUM(Q$3:Q22)) -> #REF!
A23: 21 | B23: May 26, 2025 | C23: June 26, 2025 | D23: 2025 | E23: ='Data Board'!B55 -> #REF! | F23: =IF($E23="","",E23/[1]المدخلات!$B$5) -> #REF! | G23: =IF($E23="","",SUM(E$3:E23)/[1]المدخلات!$B$5) -> #REF! | H23: =IF($E23="","",SUM(E$3:E23)) -> #REF! | I23: =IF($E23="","",E23*[1]المدخلات!$B$8) -> #REF! | J23: =IF($E23="","",E23*[1]المدخلات!$B$9) -> #REF! | K23: =IF($E23="","",E23-I23-J23) -> #REF! | N23: 0 | O23: 0 | P23: =IF($E23="","",N(L23)+N23+O23) -> #REF! | Q23: =IF($E23="","",K23-P23) -> #REF! | R23: =IF($E23="","",SUM(Q$3:Q23)) -> #REF!
A24: 22 | B24: June 27, 2025 | C24: July 30, 2025 | D24: 2025 | E24: ='Data Board'!B56 -> #REF! | F24: =IF($E24="","",E24/[1]المدخلات!$B$5) -> #REF! | G24: =IF($E24="","",SUM(E$3:E24)/[1]المدخلات!$B$5) -> #REF! | H24: =IF($E24="","",SUM(E$3:E24)) -> #REF! | I24: =IF($E24="","",E24*[1]المدخلات!$B$8) -> #REF! | J24: =IF($E24="","",E24*[1]المدخلات!$B$9) -> #REF! | K24: =IF($E24="","",E24-I24-J24) -> #REF! | N24: 0 | O24: 0 | P24: =IF($E24="","",N(L24)+N24+O24) -> #REF! | Q24: =IF($E24="","",K24-P24) -> #REF! | R24: =IF($E24="","",SUM(Q$3:Q24)) -> #REF!
A25: 23 | B25: July 31, 2025 | C25: August 28, 2025 | D25: 2025 | E25: ='Data Board'!B57 -> #REF! | F25: =IF($E25="","",E25/[1]المدخلات!$B$5) -> #REF! | G25: =IF($E25="","",SUM(E$3:E25)/[1]المدخلات!$B$5) -> #REF! | H25: =IF($E25="","",SUM(E$3:E25)) -> #REF! | I25: =IF($E25="","",E25*[1]المدخلات!$B$8) -> #REF! | J25: =IF($E25="","",E25*[1]المدخلات!$B$9) -> #REF! | K25: =IF($E25="","",E25-I25-J25) -> #REF! | N25: 0 | O25: 0 | P25: =IF($E25="","",N(L25)+N25+O25) -> #REF! | Q25: =IF($E25="","",K25-P25) -> #REF! | R25: =IF($E25="","",SUM(Q$3:Q25)) -> #REF!
A26: 24 | B26: August 29, 2025 | C26: September 29, 2025 | D26: 2025 | E26: ='Data Board'!B58 -> #REF! | F26: =IF($E26="","",E26/[1]المدخلات!$B$5) -> #REF! | G26: =IF($E26="","",SUM(E$3:E26)/[1]المدخلات!$B$5) -> #REF! | H26: =IF($E26="","",SUM(E$3:E26)) -> #REF! | I26: =IF($E26="","",E26*[1]المدخلات!$B$8) -> #REF! | J26: =IF($E26="","",E26*[1]المدخلات!$B$9) -> #REF! | K26: =IF($E26="","",E26-I26-J26) -> #REF! | L26: 11000 | M26: (عدم تواجد مدير المشروع 11 يوم عمل) | N26: 0 | O26: 0 | P26: =IF($E26="","",N(L26)+N26+O26) -> #REF! | Q26: =IF($E26="","",K26-P26) -> #REF! | R26: =IF($E26="","",SUM(Q$3:Q26)) -> #REF!
A27: 25 | B27: September 30, 2025 | C27: October 28, 2025 | D27: 2025 | E27: ='Data Board'!B59 -> #REF! | F27: =IF($E27="","",E27/[1]المدخلات!$B$5) -> #REF! | G27: =IF($E27="","",SUM(E$3:E27)/[1]المدخلات!$B$5) -> #REF! | H27: =IF($E27="","",SUM(E$3:E27)) -> #REF! | I27: =IF($E27="","",E27*[1]المدخلات!$B$8) -> #REF! | J27: =IF($E27="","",E27*[1]المدخلات!$B$9) -> #REF! | K27: =IF($E27="","",E27-I27-J27) -> #REF! | N27: 0 | O27: 0 | P27: =IF($E27="","",N(L27)+N27+O27) -> #REF! | Q27: =IF($E27="","",K27-P27) -> #REF! | R27: =IF($E27="","",SUM(Q$3:Q27)) -> #REF!
A28: 26 | B28: October 29, 2025 | C28: November 26, 2025 | D28: 2025 | E28: ='Data Board'!B60 -> #REF! | F28: =IF($E28="","",E28/[1]المدخلات!$B$5) -> #REF! | G28: =IF($E28="","",SUM(E$3:E28)/[1]المدخلات!$B$5) -> #REF! | H28: =IF($E28="","",SUM(E$3:E28)) -> #REF! | I28: =IF($E28="","",E28*[1]المدخلات!$B$8) -> #REF! | J28: =IF($E28="","",E28*[1]المدخلات!$B$9) -> #REF! | K28: =IF($E28="","",E28-I28-J28) -> #REF! | L28: 4000 | M28: (عدم تواجد فني أنظمة وتركيبات 10 يوم عمل) | N28: 0 | O28: 0 | P28: =IF($E28="","",N(L28)+N28+O28) -> #REF! | Q28: =IF($E28="","",K28-P28) -> #REF! | R28: =IF($E28="","",SUM(Q$3:Q28)) -> #REF!
A29: 27 | B29: November 27, 2025 | C29: April 20, 2026 | D29: 2026 | E29: ='Data Board'!B61 -> #REF! | F29: =IF($E29="","",E29/[1]المدخلات!$B$5) -> #REF! | G29: =IF($E29="","",SUM(E$3:E29)/[1]المدخلات!$B$5) -> #REF! | H29: =IF($E29="","",SUM(E$3:E29)) -> #REF! | I29: =IF($E29="","",E29*[1]المدخلات!$B$8) -> #REF! | J29: =IF($E29="","",E29*[1]المدخلات!$B$9) -> #REF! | K29: =IF($E29="","",E29-I29-J29) -> #REF! | L29: 22000 | M29: (عدم تواجد فني أنظمة وتركيبات 35 يوم عمل+عدم تواجد مدير المشروع 8 يوم عمل) | N29: 0 | O29: 0 | P29: =IF($E29="","",N(L29)+N29+O29) -> #REF! | Q29: =IF($E29="","",K29-P29) -> #REF! | R29: =IF($E29="","",SUM(Q$3:Q29)) -> #REF!
A30: 28 | B30: April 21, 2026 | C30: May 19, 2026 | D30: 2026 | E30: ='Data Board'!B62 -> #REF! | F30: =IF($E30="","",E30/[1]المدخلات!$B$5) -> #REF! | G30: =IF($E30="","",SUM(E$3:E30)/[1]المدخلات!$B$5) -> #REF! | H30: =IF($E30="","",SUM(E$3:E30)) -> #REF! | I30: =IF($E30="","",E30*[1]المدخلات!$B$8) -> #REF! | J30: =IF($E30="","",E30*[1]المدخلات!$B$9) -> #REF! | K30: =IF($E30="","",E30-I30-J30) -> #REF! | N30: ='Late&Supervision payment fee'!$L$13 -> #VALUE! | O30: ='Late&Supervision payment fee'!$J$28 -> 131299.78 | P30: =IF($E30="","",N(L30)+N30+O30) -> #REF! | Q30: =IF($E30="","",K30-P30) -> #REF! | R30: =IF($E30="","",SUM(Q$3:Q30)) -> #REF!
A31: 29 | B31: May 20, 2026 | C31: June 30, 2026 | D31: 2026 | E31: ='Data Board'!B63 -> #REF! | F31: =IF($E31="","",E31/[1]المدخلات!$B$5) -> #REF! | G31: =IF($E31="","",SUM(E$3:E31)/[1]المدخلات!$B$5) -> #REF! | H31: =IF($E31="","",SUM(E$3:E31)) -> #REF! | I31: =IF($E31="","",E31*[1]المدخلات!$B$8) -> #REF! | J31: =IF($E31="","",E31*[1]المدخلات!$B$9) -> #REF! | K31: =IF($E31="","",E31-I31-J31) -> #REF! | N31: ='Late&Supervision payment fee'!$L$14 -> #VALUE! | O31: ='Late&Supervision payment fee'!$J$29 -> 192473.55 | P31: =IF($E31="","",N(L31)+N31+O31) -> #REF! | Q31: =IF($E31="","",K31-P31) -> #REF! | R31: =IF($E31="","",SUM(Q$3:Q31)) -> #REF!
A32: 30 | B32: July 1, 2026 | C32: July 27, 2026 | D32: 2026 | E32: ='Data Board'!B64 -> #REF! | F32: =IF($E32="","",E32/[1]المدخلات!$B$5) -> #REF! | G32: =IF($E32="","",SUM(E$3:E32)/[1]المدخلات!$B$5) -> #REF! | H32: =IF($E32="","",SUM(E$3:E32)) -> #REF! | I32: =IF($E32="","",E32*[1]المدخلات!$B$8) -> #REF! | J32: =IF($E32="","",E32*[1]المدخلات!$B$9) -> #REF! | K32: =IF($E32="","",E32-I32-J32) -> #REF! | L32: 2000 | M32: (عدم تواجد مدير المشروع 2 يوم عمل) | N32: ='Late&Supervision payment fee'!$L$15 -> #VALUE! | O32: ='Late&Supervision payment fee'!$J$30 -> 120855.48 | P32: =IF($E32="","",N(L32)+N32+O32) -> #REF! | Q32: =IF($E32="","",K32-P32) -> #REF! | R32: =IF($E32="","",SUM(Q$3:Q32)) -> #REF!
A33: 31 | B33: July 28, 2026 | C33: August 26, 2026 | D33: 2026 | E33: ='Data Board'!B65 -> #REF! | F33: =IF($E33="","",E33/[1]المدخلات!$B$5) -> #REF! | G33: =IF($E33="","",SUM(E$3:E33)/[1]المدخلات!$B$5) -> #REF! | H33: =IF($E33="","",SUM(E$3:E33)) -> #REF! | I33: =IF($E33="","",E33*[1]المدخلات!$B$8) -> #REF! | J33: =IF($E33="","",E33*[1]المدخلات!$B$9) -> #REF! | K33: =IF($E33="","",E33-I33-J33) -> #REF! | L33: 25000 | M33: (عدم تواجد مدير المشروع 25 يوم عمل) | N33: ='Late&Supervision payment fee'!$L$16 -> #VALUE! | O33: ='Late&Supervision payment fee'!$J$31 -> 134283.87 | P33: =IF($E33="","",N(L33)+N33+O33) -> #REF! | Q33: =IF($E33="","",K33-P33) -> #REF! | R33: =IF($E33="","",SUM(Q$3:Q33)) -> #REF!
A34: 32 | B34: 46261 | C34: September 21, 2026 | D34: 2026 | E34: ='Data Board'!B66 -> #REF! | F34: =IF($E34="","",E34/[1]المدخلات!$B$5) -> #REF! | G34: =IF($E34="","",SUM(E$3:E34)/[1]المدخلات!$B$5) -> #REF! | H34: =IF($E34="","",SUM(E$3:E34)) -> #REF! | I34: =IF($E34="","",E34*[1]المدخلات!$B$8) -> #REF! | J34: =IF($E34="","",E34*[1]المدخلات!$B$9) -> #REF! | K34: =IF($E34="","",E34-I34-J34) -> #REF! | N34: ='Late&Supervision payment fee'!$L$17 -> #VALUE! | O34: ='Late&Supervision payment fee'!$J$32 -> 119512.65 | P34: =IF($E34="","",N(L34)+N34+O34) -> #REF! | Q34: =IF($E34="","",K34-P34) -> #REF! | R34: =IF($E34="","",SUM(Q$3:Q34)) -> #REF!
A35: 33 | B35: 46287 | C35: 46320 | D35: 2026 | F35: =IF($E35="","",E35/[1]المدخلات!$B$5) | G35: =IF($E35="","",SUM(E$3:E35)/[1]المدخلات!$B$5) | H35: =IF($E35="","",SUM(E$3:E35)) | I35: =IF($E35="","",E35*[1]المدخلات!$B$8) | J35: =IF($E35="","",E35*[1]المدخلات!$B$9) | K35: =IF($E35="","",E35-I35-J35) | N35: ='Late&Supervision payment fee'!L18 | O35: =IF($E35="","",SUMIF('[1]نتائج غرامة الإشراف'!$A$3:$A$35,$A35,'[1]نتائج غرامة الإشراف'!$H$3:$H$35)) | P35: =IF($E35="","",N(L35)+N35+O35) | Q35: =IF($E35="","",K35-P35) | R35: =IF($E35="","",SUM(Q$3:Q35))
A36: 34 | D36: 2026 | F36: =IF($E36="","",E36/[1]المدخلات!$B$5) | G36: =IF($E36="","",SUM(E$3:E36)/[1]المدخلات!$B$5) | H36: =IF($E36="","",SUM(E$3:E36)) | I36: =IF($E36="","",E36*[1]المدخلات!$B$8) | J36: =IF($E36="","",E36*[1]المدخلات!$B$9) | K36: =IF($E36="","",E36-I36-J36) | N36: =IF($E36="","",SUMIF('[1]نتائج غرامة التأخير'!$A$3:$A$11,$A36,'[1]نتائج غرامة التأخير'!$J$3:$J$11)) | O36: =IF($E36="","",SUMIF('[1]نتائج غرامة الإشراف'!$A$3:$A$35,$A36,'[1]نتائج غرامة الإشراف'!$H$3:$H$35)) | P36: =IF($E36="","",N(L36)+N36+O36) | Q36: =IF($E36="","",K36-P36) | R36: =IF($E36="","",SUM(Q$3:Q36))
A37: 35 | F37: =IF($E37="","",E37/[1]المدخلات!$B$5) | G37: =IF($E37="","",SUM(E$3:E37)/[1]المدخلات!$B$5) | H37: =IF($E37="","",SUM(E$3:E37)) | I37: =IF($E37="","",E37*[1]المدخلات!$B$8) | J37: =IF($E37="","",E37*[1]المدخلات!$B$9) | K37: =IF($E37="","",E37-I37-J37) | N37: =IF($E37="","",SUMIF('[1]نتائج غرامة التأخير'!$A$3:$A$11,$A37,'[1]نتائج غرامة التأخير'!$J$3:$J$11)) | O37: =IF($E37="","",SUMIF('[1]نتائج غرامة الإشراف'!$A$3:$A$35,$A37,'[1]نتائج غرامة الإشراف'!$H$3:$H$35)) | P37: =IF($E37="","",N(L37)+N37+O37) | Q37: =IF($E37="","",K37-P37) | R37: =IF($E37="","",SUM(Q$3:Q37))
A38: 36 | F38: =IF($E38="","",E38/[1]المدخلات!$B$5) | G38: =IF($E38="","",SUM(E$3:E38)/[1]المدخلات!$B$5) | H38: =IF($E38="","",SUM(E$3:E38)) | I38: =IF($E38="","",E38*[1]المدخلات!$B$8) | J38: =IF($E38="","",E38*[1]المدخلات!$B$9) | K38: =IF($E38="","",E38-I38-J38) | N38: =IF($E38="","",SUMIF('[1]نتائج غرامة التأخير'!$A$3:$A$11,$A38,'[1]نتائج غرامة التأخير'!$J$3:$J$11)) | O38: =IF($E38="","",SUMIF('[1]نتائج غرامة الإشراف'!$A$3:$A$35,$A38,'[1]نتائج غرامة الإشراف'!$H$3:$H$35)) | P38: =IF($E38="","",N(L38)+N38+O38) | Q38: =IF($E38="","",K38-P38) | R38: =IF($E38="","",SUM(Q$3:Q38))
A40: قيمة العقد المعتمدة | B40: ='Progress Report'!J3 -> #VALUE! | D40: البند | F40: القيمة (ريال) | G40: % من العقد | J40: السنة | K40: عدد المستخلصات | L40: قيمة الأعمال | M40: % من العقد
A41: مدة المشروع (يوم عمل) | B41: 839 | D41: إجمالي الأعمال المنجزة (المفوتر) | F41: =E2 -> #REF! | G41: =($F$41/$B$40) -> #REF! | J41: 2023 | K41: =COUNTIF(D3:D38,J41) -> 4 | L41: =SUMIF(D1:D38,J41,E1:E38) -> #REF! | M41: =L41/B40 -> #REF!
...

Sheet Progress Report
A3: =COUNT(A5:A354) -> 29 | B3: الإجمالي | I3: =SUM(I5:I354) -> #VALUE! | J3: =SUM(J5:J354) -> #VALUE! | K3: =SUM(K5:K354) -> #VALUE! | L3: =SUM(L5:L354) -> 6052370 | M3: =IF(J3=0,0,L3/J3) -> #VALUE! | P3: =SUM(P5:P354) -> #VALUE! | Q3: =IF(J3=0,0,P3/J3) -> #VALUE!
A4: م | B4: رقم البند | C4: وصف البند | D4: الوحدة | E4: سعر الوحدة (SAR) | F4: الكمية الأصلية (B.Q) | G4: الكمية المعتمدة (C.R) | H4: فرق الكمية | I4: القيمة الأصلية (SAR) | J4: القيمة المعتمدة (SAR) | K4: فرق القيمة (أمر التغيير) | L4: إجمالي المفوتر (SAR) | M4: نسبة الإنجاز الفعلية % | N4: الكمية المنجزة | O4: الكمية المتبقية | P4: القيمة المتبقية (SAR) | Q4: نسبة المتبقي % | R4: المتبقي | S4: الحالة | T4: حالة أمر التغيير | U4: المجموعة | V4: مفتاح ترتيب المتبقي | W4: مفتاح ترتيب الفرق | X4: صف البند في SUMMARY | Y4: فرق عن TOTAL
A5: =IF($X5="","",ROW()-4) -> 1 | B5: =IF($X5="","",INDEX('Tracker&Invoice'!$A:$A,$X5)) -> D-001 | C5: =IF($X5="","",INDEX('Tracker&Invoice'!$B:$B,$X5)) -> التصاميم التفصيلية وتصاميم المرحلة الثالثة Stage 3 Design Package | D5: =IF($X5="","",INDEX('Tracker&Invoice'!$E:$E,$X5)) -> عدد | E5: =IF($X5="","",INDEX('Tracker&Invoice'!$F:$F,$X5)) -> 2840000 | F5: =IF($X5="","",INDEX('Tracker&Invoice'!$C:$C,$X5)) -> 1 | G5: =IF($X5="","",INDEX('Tracker&Invoice'!$D:$D,$X5)) -> 1 | H5: =IF($X5="","",G5-F5) -> 0 | I5: =IF($X5="","",F5*E5) -> 2840000 | J5: =IF($X5="","",G5*E5) -> 2840000 | K5: =IF($X5="","",J5-I5) -> 0 | L5: =IF($X5="","",SUMIF('Details Data Board'!$C$3:$C$6001,B5,'Details Data Board'!$I$3:$I$6001)) -> 2840000 | M5: =IF($X5="","",IF(J5=0,0,L5/J5)) -> 1 | N5: =IF($X5="","",M5*G5) -> 1 | O5: =IF($X5="","",G5-N5) -> 0 | P5: =IF($X5="","",J5-L5) -> 0 | Q5: =IF($X5="","",IF(J5=0,0,P5/J5)) -> 0 | R5: =IF($X5="","",IF(INT(O5)=O5,TEXT(O5,"#,##0"),TEXT(O5,"#,##0.00"))&" "&D5&" | "&TEXT(P5,"#,##0")&" ريال | "&TEXT(Q5,"0.0%")) -> 0 عدد | 0 ريال | 0.0% | S5: =IF($X5="","",IF(L5<=0,"لم يبدأ",IF(P5<-0.5,"تجاوز 100% - راجع",IF(P5<=0.5,"مكتمل","جاري")))) -> مكتمل | T5: =IF($X5="","",IF(AND(F5=0,G5>0),"جديد بأمر التغيير",IF(AND(G5=0,F5>0),"ملغي",IF(G5>F5,"زيادة",IF(G5<F5,"نقص","بدون تغيير"))))) -> بدون تغيير | U5: =IF($X5="","",IFERROR(LEFT(B5,FIND("-",B5)-1),B5)) -> D | V5: =IF($X5="","",P5+ROW()/1000000) -> 5e-06 | W5: =IF($X5="","",K5+ROW()/1000000) -> 5e-06 | X5: =IFERROR(MATCH(ROW()-4,'Details Data Board'!$A$3:$A$6001,0)+1,"") -> 4 | Y5: =IF($X5="",0,ROUND(INDEX('Tracker&Invoice'!$G:$G,$X5)-J5,2)) -> 0
A6: =IF($X6="","",ROW()-4) -> 2 | B6: =IF($X6="","",INDEX('Tracker&Invoice'!$A:$A,$X6)) -> D-002 | C6: =IF($X6="","",INDEX('Tracker&Invoice'!$B:$B,$X6)) -> الهندسة والتصميم IFC, Shop drawings and Stage 4 drawings | D6: =IF($X6="","",INDEX('Tracker&Invoice'!$E:$E,$X6)) -> عدد | E6: =IF($X6="","",INDEX('Tracker&Invoice'!$F:$F,$X6)) -> 2630000 | F6: =IF($X6="","",INDEX('Tracker&Invoice'!$C:$C,$X6)) -> 1 | G6: =IF($X6="","",INDEX('Tracker&Invoice'!$D:$D,$X6)) -> 1 | H6: =IF($X6="","",G6-F6) -> 0 | I6: =IF($X6="","",F6*E6) -> 2630000 | J6: =IF($X6="","",G6*E6) -> 2630000 | K6: =IF($X6="","",J6-I6) -> 0 | L6: =IF($X6="","",SUMIF('Details Data Board'!$C$3:$C$6001,B6,'Details Data Board'!$I$3:$I$6001)) -> 1578000 | M6: =IF($X6="","",IF(J6=0,0,L6/J6)) -> 0.6 | N6: =IF($X6="","",M6*G6) -> 0.6 | O6: =IF($X6="","",G6-N6) -> 0.4 | P6: =IF($X6="","",J6-L6) -> 1052000 | Q6: =IF($X6="","",IF(J6=0,0,P6/J6)) -> 0.4 | R6: =IF($X6="","",IF(INT(O6)=O6,TEXT(O6,"#,##0"),TEXT(O6,"#,##0.00"))&" "&D6&" | "&TEXT(P6,"#,##0")&" ريال | "&TEXT(Q6,"0.0%")) -> 0.40 عدد | 1,052,000 ريال | 40.0% | S6: =IF($X6="","",IF(L6<=0,"لم يبدأ",IF(P6<-0.5,"تجاوز 100% - راجع",IF(P6<=0.5,"مكتمل","جاري")))) -> جاري | T6: =IF($X6="","",IF(AND(F6=0,G6>0),"جديد بأمر التغيير",IF(AND(G6=0,F6>0),"ملغي",IF(G6>F6,"زيادة",IF(G6<F6,"نقص","بدون تغيير"))))) -> بدون تغيير | U6: =IF($X6="","",IFERROR(LEFT(B6,FIND("-",B6)-1),B6)) -> D | V6: =IF($X6="","",P6+ROW()/1000000) -> 1052000 | W6: =IF($X6="","",K6+ROW()/1000000) -> 6e-06 | X6: =IFERROR(MATCH(ROW()-4,'Details Data Board'!$A$3:$A$6001,0)+1,"") -> 17 | Y6: =IF($X6="",0,ROUND(INDEX('Tracker&Invoice'!$G:$G,$X6)-J6,2)) -> 0
A7: =IF($X7="","",ROW()-4) -> 3 | B7: =IF($X7="","",INDEX('Tracker&Invoice'!$A:$A,$X7)) -> D-003 | C7: =IF($X7="","",INDEX('Tracker&Invoice'!$B:$B,$X7)) -> تدريب المشغلين وموظفي الصيانة Training of Operators and Maintenance Personnel | D7: =IF($X7="","",INDEX('Tracker&Invoice'!$E:$E,$X7)) -> عدد | E7: =IF($X7="","",INDEX('Tracker&Invoice'!$F:$F,$X7)) -> 110000 | F7: =IF($X7="","",INDEX('Tracker&Invoice'!$C:$C,$X7)) -> 1 | G7: =IF($X7="","",INDEX('Tracker&Invoice'!$D:$D,$X7)) -> 1 | H7: =IF($X7="","",G7-F7) -> 0 | I7: =IF($X7="","",F7*E7) -> 110000 | J7: =IF($X7="","",G7*E7) -> 110000 | K7: =IF($X7="","",J7-I7) -> 0 | L7: =IF($X7="","",SUMIF('Details Data Board'!$C$3:$C$6001,B7,'Details Data Board'!$I$3:$I$6001)) -> 0 | M7: =IF($X7="","",IF(J7=0,0,L7/J7)) -> 0 | N7: =IF($X7="","",M7*G7) -> 0 | O7: =IF($X7="","",G7-N7) -> 1 | P7: =IF($X7="","",J7-L7) -> 110000 | Q7: =IF($X7="","",IF(J7=0,0,P7/J7)) -> 1 | R7: =IF($X7="","",IF(INT(O7)=O7,TEXT(O7,"#,##0"),TEXT(O7,"#,##0.00"))&" "&D7&" | "&TEXT(P7,"#,##0")&" ريال | "&TEXT(Q7,"0.0%")) -> 1 عدد | 110,000 ريال | 100.0% | S7: =IF($X7="","",IF(L7<=0,"لم يبدأ",IF(P7<-0.5,"تجاوز 100% - راجع",IF(P7<=0.5,"مكتمل","جاري")))) -> لم يبدأ | T7: =IF($X7="","",IF(AND(F7=0,G7>0),"جديد بأمر التغيير",IF(AND(G7=0,F7>0),"ملغي",IF(G7>F7,"زيادة",IF(G7<F7,"نقص","بدون تغيير"))))) -> بدون تغيير | U7: =IF($X7="","",IFERROR(LEFT(B7,FIND("-",B7)-1),B7)) -> D | V7: =IF($X7="","",P7+ROW()/1000000) -> 110000 | W7: =IF($X7="","",K7+ROW()/1000000) -> 7e-06 | X7: =IFERROR(MATCH(ROW()-4,'Details Data Board'!$A$3:$A$6001,0)+1,"") -> 48 | Y7: =IF($X7="",0,ROUND(INDEX('Tracker&Invoice'!$G:$G,$X7)-J7,2)) -> 0
A8: =IF($X8="","",ROW()-4) -> 4 | B8: =IF($X8="","",INDEX('Tracker&Invoice'!$A:$A,$X8)) -> BQ-001 | C8: =IF($X8="","",INDEX('Tracker&Invoice'!$B:$B,$X8)) -> محمول شبكة مركزي مع جميع الكابلات ذات الصلة والملحقات والأجهزة التمهيدية وأجهزة الشبكة Central Redundant Network Core Switch with all related cabling, accessories, prepherals and network devices | D8: =IF($X8="","",INDEX('Tracker&Invoice'!$E:$E,$X8)) -> عدد | E8: =IF($X8="","",INDEX('Tracker&Invoice'!$F:$F,$X8)) -> 130000 | F8: =IF($X8="","",INDEX('Tracker&Invoice'!$C:$C,$X8)) -> 4 | G8: =IF($X8="","",INDEX('Tracker&Invoice'!$D:$D,$X8)) -> 4 | H8: =IF($X8="","",G8-F8) -> 0 | I8: =IF($X8="","",F8*E8) -> 520000 | J8: =IF($X8="","",G8*E8) -> 520000 | K8: =IF($X8="","",J8-I8) -> 0 | L8: =IF($X8="","",SUMIF('Details Data Board'!$C$3:$C$6001,B8,'Details Data Board'!$I$3:$I$6001)) -> 416000 | M8: =IF($X8="","",IF(J8=0,0,L8/J8)) -> 0.8 | N8: =IF($X8="","",M8*G8) -> 3.2 | O8: =IF($X8="","",G8-N8) -> 0.8 | P8: =IF($X8="","",J8-L8) -> 104000 | Q8: =IF($X8="","",IF(J8=0,0,P8/J8)) -> 0.2 | R8: =IF($X8="","",IF(INT(O8)=O8,TEXT(O8,"#,##0"),TEXT(O8,"#,##0.00"))&" "&D8&" | "&TEXT(P8,"#,##0")&" ريال | "&TEXT(Q8,"0.0%")) -> 0.80 عدد | 104,000 ريال | 20.0% | S8: =IF($X8="","",IF(L8<=0,"لم يبدأ",IF(P8<-0.5,"تجاوز 100% - راجع",IF(P8<=0.5,"مكتمل","جاري")))) -> جاري | T8: =IF($X8="","",IF(AND(F8=0,G8>0),"جديد بأمر التغيير",IF(AND(G8=0,F8>0),"ملغي",IF(G8>F8,"زيادة",IF(G8<F8,"نقص","بدون تغيير"))))) -> بدون تغيير | U8: =IF($X8="","",IFERROR(LEFT(B8,FIND("-",B8)-1),B8)) -> BQ | V8: =IF($X8="","",P8+ROW()/1000000) -> 104000 | W8: =IF($X8="","",K8+ROW()/1000000) -> 8e-06 | X8: =IFERROR(MATCH(ROW()-4,'Details Data Board'!$A$3:$A$6001,0)+1,"") -> 59 | Y8: =IF($X8="",0,ROUND(INDEX('Tracker&Invoice'!$G:$G,$X8)-J8,2)) -> 0
A9: =IF($X9="","",ROW()-4) -> 5 | B9: =IF($X9="","",INDEX('Tracker&Invoice'!$A:$A,$X9)) -> BQ-002 | C9: =IF($X9="","",INDEX('Tracker&Invoice'!$B:$B,$X9)) -> محول شبكة جيجابايت مع جميع الكابلات ذات الصلة والملحقات والأجهزة التمهيدية وأجهزة الشبكة Gigabit Network Switch with all related cabling, accessories, prepherals and network devices | D9: =IF($X9="","",INDEX('Tracker&Invoice'!$E:$E,$X9)) -> عدد | E9: =IF($X9="","",INDEX('Tracker&Invoice'!$F:$F,$X9)) -> 19600 | F9: =IF($X9="","",INDEX('Tracker&Invoice'!$C:$C,$X9)) -> 10 | G9: =IF($X9="","",INDEX('Tracker&Invoice'!$D:$D,$X9)) -> 10 | H9: =IF($X9="","",G9-F9) -> 0 | I9: =IF($X9="","",F9*E9) -> 196000 | J9: =IF($X9="","",G9*E9) -> 196000 | K9: =IF($X9="","",J9-I9) -> 0 | L9: =IF($X9="","",SUMIF('Details Data Board'!$C$3:$C$6001,B9,'Details Data Board'!$I$3:$I$6001)) -> 78400 | M9: =IF($X9="","",IF(J9=0,0,L9/J9)) -> 0.4 | N9: =IF($X9="","",M9*G9) -> 4 | O9: =IF($X9="","",G9-N9) -> 6 | P9: =IF($X9="","",J9-L9) -> 117600 | Q9: =IF($X9="","",IF(J9=0,0,P9/J9)) -> 0.6 | R9: =IF($X9="","",IF(INT(O9)=O9,TEXT(O9,"#,##0"),TEXT(O9,"#,##0.00"))&" "&D9&" | "&TEXT(P9,"#,##0")&" ريال | "&TEXT(Q9,"0.0%")) -> 6 عدد | 117,600 ريال | 60.0% | S9: =IF($X9="","",IF(L9<=0,"لم يبدأ",IF(P9<-0.5,"تجاوز 100% - راجع",IF(P9<=0.5,"مكتمل","جاري")))) -> جاري | T9: =IF($X9="","",IF(AND(F9=0,G9>0),"جديد بأمر التغيير",IF(AND(G9=0,F9>0),"ملغي",IF(G9>F9,"زيادة",IF(G9<F9,"نقص","بدون تغيير"))))) -> بدون تغيير | U9: =IF($X9="","",IFERROR(LEFT(B9,FIND("-",B9)-1),B9)) -> BQ | V9: =IF($X9="","",P9+ROW()/1000000) -> 117600 | W9: =IF($X9="","",K9+ROW()/1000000) -> 9e-06 | X9: =IFERROR(MATCH(ROW()-4,'Details Data Board'!$A$3:$A$6001,0)+1,"") -> 79 | Y9: =IF($X9="",0,ROUND(INDEX('Tracker&Invoice'!$G:$G,$X9)-J9,2)) -> 0
A10: =IF($X10="","",ROW()-4) -> 6 | B10: =IF($X10="","",INDEX('Tracker&Invoice'!$A:$A,$X10)) -> BQ-003 | C10: =IF($X10="","",INDEX('Tracker&Invoice'!$B:$B,$X10)) -> كابينة المعدات الميدانية بما في ذلك جميع إمدادات الطاقة وكابلات الطاقة والبيانات إلى FEC وجميع المعدات الأمنية والمفاتيح الصناعية ولوحات التصحيح و CBs و TB وجميع الملحقات الكهربائية والاتصالات ذات الصلة وجميع الأعمال اللازمة لإكمال البند. Field Equipment cabinets including all power supplies, power and data cabling to the FEC and all security equipment, Industrial switches, patch panels, CBs, TBs, and all related electrical and communications accessories and all necessary work to complete the item. | D10: =IF($X10="","",INDEX('Tracker&Invoice'!$E:$E,$X10)) -> عدد | E10: =IF($X10="","",INDEX('Tracker&Invoice'!$F:$F,$X10)) -> 23700 | F10: =IF($X10="","",INDEX('Tracker&Invoice'!$C:$C,$X10)) -> 66 | G10: =IF($X10="","",INDEX('Tracker&Invoice'!$D:$D,$X10)) -> 61 | H10: =IF($X10="","",G10-F10) -> -5 | I10: =IF($X10="","",F10*E10) -> 1564200 | J10: =IF($X10="","",G10*E10) -> 1445700 | K10: =IF($X10="","",J10-I10) -> -118500 | L10: =IF($X10="","",SUMIF('Details Data Board'!$C$3:$C$6001,B10,'Details Data Board'!$I$3:$I$6001)) -> 1139970 | M10: =IF($X10="","",IF(J10=0,0,L10/J10)) -> 0.78852459 | N10: =IF($X10="","",M10*G10) -> 48.1 | O10: =IF($X10="","",G10-N10) -> 12.9 | P10: =IF($X10="","",J10-L10) -> 305730 | Q10: =IF($X10="","",IF(J10=0,0,P10/J10)) -> 0.21147541 | R10: =IF($X10="","",IF(INT(O10)=O10,TEXT(O10,"#,##0"),TEXT(O10,"#,##0.00"))&" "&D10&" | "&TEXT(P10,"#,##0")&" ريال | "&TEXT(Q10,"0.0%")) -> 12.90 عدد | 305,730 ريال | 21.1% | S10: =IF($X10="","",IF(L10<=0,"لم يبدأ",IF(P10<-0.5,"تجاوز 100% - راجع",IF(P10<=0.5,"مكتمل","جاري")))) -> جاري | T10: =IF($X10="","",IF(AND(F10=0,G10>0),"جديد بأمر التغيير",IF(AND(G10=0,F10>0),"ملغي",IF(G10>F10,"زيادة",IF(G10<F10,"نقص","بدون تغيير"))))) -> نقص | U10: =IF($X10="","",IFERROR(LEFT(B10,FIND("-",B10)-1),B10)) -> BQ | V10: =IF($X10="","",P10+ROW()/1000000) -> 305730 | W10: =IF($X10="","",K10+ROW()/1000000) -> -118500 | X10: =IFERROR(MATCH(ROW()-4,'Details Data Board'!$A$3:$A$6001,0)+1,"") -> 103 | Y10: =IF($X10="",0,ROUND(INDEX('Tracker&Invoice'!$G:$G,$X10)-J10,2)) -> 0
A11: =IF($X11="","",ROW()-4) -> 7 | B11: =IF($X11="","",INDEX('Tracker&Invoice'!$A:$A,$X11)) -> ITEM | C11: =IF($X11="","",INDEX('Tracker&Invoice'!$B:$B,$X11)) -> Description | D11: =IF($X11="","",INDEX('Tracker&Invoice'!$E:$E,$X11)) -> UNITE | E11: =IF('Tracker&Invoice'!D139:D140="","",INDEX('Tracker&Invoice'!$F:$F,$X11)) -> #VALUE! | F11: =IF($X11="","",INDEX('Tracker&Invoice'!$C:$C,$X11)) -> OLD QUANTITY | G11: =IF($X11="","",INDEX('Tracker&Invoice'!$D:$D,$X11)) -> C.R QUANTITY | H11: =IF($X11="","",G11-F11) -> #VALUE! | I11: =IF($X11="","",F11*E11) -> #VALUE! | J11: =IF($X11="","",G11*E11) -> #VALUE! | K11: =IF($X11="","",J11-I11) -> #VALUE! | L11: =IF($X11="","",SUMIF('Details Data Board'!$C$3:$C$6001,B11,'Details Data Board'!$I$3:$I$6001)) -> 0 | M11: =IF($X11="","",IF(J11=0,0,L11/J11)) -> #VALUE! | N11: =IF($X11="","",M11*G11) -> #VALUE! | O11: =IF($X11="","",G11-N11) -> #VALUE! | P11: =IF($X11="","",J11-L11) -> #VALUE! | Q11: =IF($X11="","",IF(J11=0,0,P11/J11)) -> #VALUE! | R11: =IF($X11="","",IF(INT(O11)=O11,TEXT(O11,"#,##0"),TEXT(O11,"#,##0.00"))&" "&D11&" | "&TEXT(P11,"#,##0")&" ريال | "&TEXT(Q11,"0.0%")) -> #VALUE! | S11: =IF($X11="","",IF(L11<=0,"لم يبدأ",IF(P11<-0.5,"تجاوز 100% - راجع",IF(P11<=0.5,"مكتمل","جاري")))) -> لم يبدأ | T11: =IF($X11="","",IF(AND(F11=0,G11>0),"جديد بأمر التغيير",IF(AND(G11=0,F11>0),"ملغي",IF(G11>F11,"زيادة",IF(G11<F11,"نقص","بدون تغيير"))))) -> نقص | U11: =IF($X11="","",IFERROR(LEFT(B11,FIND("-",B11)-1),B11)) -> ITEM | V11: =IF($X11="","",P11+ROW()/1000000) -> #VALUE! | W11: =IF($X11="","",K11+ROW()/1000000) -> #VALUE! | X11: =IFERROR(MATCH(ROW()-4,'Details Data Board'!$A$3:$A$6001,0)+1,"") -> 137 | Y11: =IF($X11="",0,ROUND(INDEX('Tracker&Invoice'!$G:$G,$X11)-J11,2)) -> #VALUE!
A12: =IF($X12="","",ROW()-4) -> 8 | B12: =IF($X12="","",INDEX('Tracker&Invoice'!$A:$A,$X12)) -> 0 | C12: =IF($X12="","",INDEX('Tracker&Invoice'!$B:$B,$X12)) -> Overall Completion percentage | D12: =IF($X12="","",INDEX('Tracker&Invoice'!$E:$E,$X12)) -> 0 | E12: =IF($X12="","",INDEX('Tracker&Invoice'!$F:$F,$X12)) -> 0 | F12: =IF($X12="","",INDEX('Tracker&Invoice'!$C:$C,$X12)) -> 0 | G12: =IF($X12="","",INDEX('Tracker&Invoice'!$D:$D,$X12)) -> 0 | H12: =IF($X12="","",G12-F12) -> 0 | I12: =IF($X12="","",F12*E12) -> 0 | J12: =IF($X12="","",G12*E12) -> 0 | K12: =IF($X12="","",J12-I12) -> 0 | L12: =IF($X12="","",SUMIF('Details Data Board'!$C$3:$C$6001,B12,'Details Data Board'!$I$3:$I$6001)) -> 0 | M12: =IF($X12="","",IF(J12=0,0,L12/J12)) -> 0 | N12: =IF($X12="","",M12*G12) -> 0 | O12: =IF($X12="","",G12-N12) -> 0 | P12: =IF($X12="","",J12-L12) -> 0 | Q12: =IF($X12="","",IF(J12=0,0,P12/J12)) -> 0 | R12: =IF($X12="","",IF(INT(O12)=O12,TEXT(O12,"#,##0"),TEXT(O12,"#,##0.00"))&" "&D12&" | "&TEXT(P12,"#,##0")&" ريال | "&TEXT(Q12,"0.0%")) -> 0 0 | 0 ريال | 0.0% | S12: =IF($X12="","",IF(L12<=0,"لم يبدأ",IF(P12<-0.5,"تجاوز 100% - راجع",IF(P12<=0.5,"مكتمل","جاري")))) -> لم يبدأ | T12: =IF($X12="","",IF(AND(F12=0,G12>0),"جديد بأمر التغيير",IF(AND(G12=0,F12>0),"ملغي",IF(G12>F12,"زيادة",IF(G12<F12,"نقص","بدون تغيير"))))) -> بدون تغيير | U12: =IF($X12="","",IFERROR(LEFT(B12,FIND("-",B12)-1),B12)) -> 0 | V12: =IF($X12="","",P12+ROW()/1000000) -> 1.2e-05 | W12: =IF($X12="","",K12+ROW()/1000000) -> 1.2e-05 | X12: =IFERROR(MATCH(ROW()-4,'Details Data Board'!$A$3:$A$6001,0)+1,"") -> 173 | Y12: =IF($X12="",0,ROUND(INDEX('Tracker&Invoice'!$G:$G,$X12)-J12,2)) -> 0
A13: =IF($X13="","",ROW()-4) -> 9 | B13: =IF($X13="","",INDEX('Tracker&Invoice'!$A:$A,$X13)) -> 0 | C13: =IF($X13="","",INDEX('Tracker&Invoice'!$B:$B,$X13)) -> INVOICE #13 | D13: =IF($X13="","",INDEX('Tracker&Invoice'!$E:$E,$X13)) -> 0 | E13: =IF($X13="","",INDEX('Tracker&Invoice'!$F:$F,$X13)) -> 0 | F13: =IF($X13="","",INDEX('Tracker&Invoice'!$C:$C,$X13)) -> 0 | G13: =IF($X13="","",INDEX('Tracker&Invoice'!$D:$D,$X13)) -> 0 | H13: =IF($X13="","",G13-F13) -> 0 | I13: =IF($X13="","",F13*E13) -> 0 | J13: =IF($X13="","",G13*E13) -> 0 | K13: =IF($X13="","",J13-I13) -> 0 | L13: =IF($X13="","",SUMIF('Details Data Board'!$C$3:$C$6001,B13,'Details Data Board'!$I$3:$I$6001)) -> 0 | M13: =IF($X13="","",IF(J13=0,0,L13/J13)) -> 0 | N13: =IF($X13="","",M13*G13) -> 0 | O13: =IF($X13="","",G13-N13) -> 0 | P13: =IF($X13="","",J13-L13) -> 0 | Q13: =IF($X13="","",IF(J13=0,0,P13/J13)) -> 0 | R13: =IF($X13="","",IF(INT(O13)=O13,TEXT(O13,"#,##0"),TEXT(O13,"#,##0.00"))&" "&D13&" | "&TEXT(P13,"#,##0")&" ريال | "&TEXT(Q13,"0.0%")) -> 0 0 | 0 ريال | 0.0% | S13: =IF($X13="","",IF(L13<=0,"لم يبدأ",IF(P13<-0.5,"تجاوز 100% - راجع",IF(P13<=0.5,"مكتمل","جاري")))) -> لم يبدأ | T13: =IF($X13="","",IF(AND(F13=0,G13>0),"جديد بأمر التغيير",IF(AND(G13=0,F13>0),"ملغي",IF(G13>F13,"زيادة",IF(G13<F13,"نقص","بدون تغيير"))))) -> بدون تغيير | U13: =IF($X13="","",IFERROR(LEFT(B13,FIND("-",B13)-1),B13)) -> 0 | V13: =IF($X13="","",P13+ROW()/1000000) -> 1.3e-05 | W13: =IF($X13="","",K13+ROW()/1000000) -> 1.3e-05 | X13: =IFERROR(MATCH(ROW()-4,'Details Data Board'!$A$3:$A$6001,0)+1,"") -> 195 | Y13: =IF($X13="",0,ROUND(INDEX('Tracker&Invoice'!$G:$G,$X13)-J13,2)) -> 0
A14: =IF($X14="","",ROW()-4) -> 10 | B14: =IF($X14="","",INDEX('Tracker&Invoice'!$A:$A,$X14)) -> 0 | C14: =IF($X14="","",INDEX('Tracker&Invoice'!$B:$B,$X14)) -> INVOICE #13 | D14: =IF($X14="","",INDEX('Tracker&Invoice'!$E:$E,$X14)) -> 0 | E14: =IF($X14="","",INDEX('Tracker&Invoice'!$F:$F,$X14)) -> 0 | F14: =IF($X14="","",INDEX('Tracker&Invoice'!$C:$C,$X14)) -> 0 | G14: =IF($X14="","",INDEX('Tracker&Invoice'!$D:$D,$X14)) -> 0 | H14: =IF($X14="","",G14-F14) -> 0 | I14: =IF($X14="","",F14*E14) -> 0 | J14: =IF($X14="","",G14*E14) -> 0 | K14: =IF($X14="","",J14-I14) -> 0 | L14: =IF($X14="","",SUMIF('Details Data Board'!$C$3:$C$6001,B14,'Details Data Board'!$I$3:$I$6001)) -> 0 | M14: =IF($X14="","",IF(J14=0,0,L14/J14)) -> 0 | N14: =IF($X14="","",M14*G14) -> 0 | O14: =IF($X14="","",G14-N14) -> 0 | P14: =IF($X14="","",J14-L14) -> 0 | Q14: =IF($X14="","",IF(J14=0,0,P14/J14)) -> 0 | R14: =IF($X14="","",IF(INT(O14)=O14,TEXT(O14,"#,##0"),TEXT(O14,"#,##0.00"))&" "&D14&" | "&TEXT(P14,"#,##0")&" ريال | "&TEXT(Q14,"0.0%")) -> 0 0 | 0 ريال | 0.0% | S14: =IF($X14="","",IF(L14<=0,"لم يبدأ",IF(P14<-0.5,"تجاوز 100% - راجع",IF(P14<=0.5,"مكتمل","جاري")))) -> لم يبدأ | T14: =IF($X14="","",IF(AND(F14=0,G14>0),"جديد بأمر التغيير",IF(AND(G14=0,F14>0),"ملغي",IF(G14>F14,"زيادة",IF(G14<F14,"نقص","بدون تغيير"))))) -> بدون تغيير | U14: =IF($X14="","",IFERROR(LEFT(B14,FIND("-",B14)-1),B14)) -> 0 | V14: =IF($X14="","",P14+ROW()/1000000) -> 1.4e-05 | W14: =IF($X14="","",K14+ROW()/1000000) -> 1.4e-05 | X14: =IFERROR(MATCH(ROW()-4,'Details Data Board'!$A$3:$A$6001,0)+1,"") -> 217 | Y14: =IF($X14="",0,ROUND(INDEX('Tracker&Invoice'!$G:$G,$X14)-J14,2)) -> 0
A15: =IF($X15="","",ROW()-4) -> 11 | B15: =IF($X15="","",INDEX('Tracker&Invoice'!$A:$A,$X15)) -> 0 | C15: =IF($X15="","",INDEX('Tracker&Invoice'!$B:$B,$X15)) -> INVOICE #12 | D15: =IF($X15="","",INDEX('Tracker&Invoice'!$E:$E,$X15)) -> 0 | E15: =IF($X15="","",INDEX('Tracker&Invoice'!$F:$F,$X15)) -> 0 | F15: =IF($X15="","",INDEX('Tracker&Invoice'!$C:$C,$X15)) -> 0 | G15: =IF($X15="","",INDEX('Tracker&Invoice'!$D:$D,$X15)) -> 0 | H15: =IF($X15="","",G15-F15) -> 0 | I15: =IF($X15="","",F15*E15) -> 0 | J15: =IF($X15="","",G15*E15) -> 0 | K15: =IF($X15="","",J15-I15) -> 0 | L15: =IF($X15="","",SUMIF('Details Data Board'!$C$3:$C$6001,B15,'Details Data Board'!$I$3:$I$6001)) -> 0 | M15: =IF($X15="","",IF(J15=0,0,L15/J15)) -> 0 | N15: =IF($X15="","",M15*G15) -> 0 | O15: =IF($X15="","",G15-N15) -> 0 | P15: =IF($X15="","",J15-L15) -> 0 | Q15: =IF($X15="","",IF(J15=0,0,P15/J15)) -> 0 | R15: =IF($X15="","",IF(INT(O15)=O15,TEXT(O15,"#,##0"),TEXT(O15,"#,##0.00"))&" "&D15&" | "&TEXT(P15,"#,##0")&" ريال | "&TEXT(Q15,"0.0%")) -> 0 0 | 0 ريال | 0.0% | S15: =IF($X15="","",IF(L15<=0,"لم يبدأ",IF(P15<-0.5,"تجاوز 100% - راجع",IF(P15<=0.5,"مكتمل","جاري")))) -> لم يبدأ | T15: =IF($X15="","",IF(AND(F15=0,G15>0),"جديد بأمر التغيير",IF(AND(G15=0,F15>0),"ملغي",IF(G15>F15,"زيادة",IF(G15<F15,"نقص","بدون تغيير"))))) -> بدون تغيير | U15: =IF($X15="","",IFERROR(LEFT(B15,FIND("-",B15)-1),B15)) -> 0 | V15: =IF($X15="","",P15+ROW()/1000000) -> 1.5e-05 | W15: =IF($X15="","",K15+ROW()/1000000) -> 1.5e-05 | X15: =IFERROR(MATCH(ROW()-4,'Details Data Board'!$A$3:$A$6001,0)+1,"") -> 239 | Y15: =IF($X15="",0,ROUND(INDEX('Tracker&Invoice'!$G:$G,$X15)-J15,2)) -> 0
A16: =IF($X16="","",ROW()-4) -> 12 | B16: =IF($X16="","",INDEX('Tracker&Invoice'!$A:$A,$X16)) -> 0 | C16: =IF($X16="","",INDEX('Tracker&Invoice'!$B:$B,$X16)) -> 0 | D16: =IF($X16="","",INDEX('Tracker&Invoice'!$E:$E,$X16)) -> 0 | E16: =IF($X16="","",INDEX('Tracker&Invoice'!$F:$F,$X16)) -> 0 | F16: =IF($X16="","",INDEX('Tracker&Invoice'!$C:$C,$X16)) -> 0 | G16: =IF($X16="","",INDEX('Tracker&Invoice'!$D:$D,$X16)) -> 0 | H16: =IF($X16="","",G16-F16) -> 0 | I16: =IF($X16="","",F16*E16) -> 0 | J16: =IF($X16="","",G16*E16) -> 0 | K16: =IF($X16="","",J16-I16) -> 0 | L16: =IF($X16="","",SUMIF('Details Data Board'!$C$3:$C$6001,B16,'Details Data Board'!$I$3:$I$6001)) -> 0 | M16: =IF($X16="","",IF(J16=0,0,L16/J16)) -> 0 | N16: =IF($X16="","",M16*G16) -> 0 | O16: =IF($X16="","",G16-N16) -> 0 | P16: =IF($X16="","",J16-L16) -> 0 | Q16: =IF($X16="","",IF(J16=0,0,P16/J16)) -> 0 | R16: =IF($X16="","",IF(INT(O16)=O16,TEXT(O16,"#,##0"),TEXT(O16,"#,##0.00"))&" "&D16&" | "&TEXT(P16,"#,##0")&" ريال | "&TEXT(Q16,"0.0%")) -> 0 0 | 0 ريال | 0.0% | S16: =IF($X16="","",IF(L16<=0,"لم يبدأ",IF(P16<-0.5,"تجاوز 100% - راجع",IF(P16<=0.5,"مكتمل","جاري")))) -> لم يبدأ | T16: =IF($X16="","",IF(AND(F16=0,G16>0),"جديد بأمر التغيير",IF(AND(G16=0,F16>0),"ملغي",IF(G16>F16,"زيادة",IF(G16<F16,"نقص","بدون تغيير"))))) -> بدون تغيير | U16: =IF($X16="","",IFERROR(LEFT(B16,FIND("-",B16)-1),B16)) -> 0 | V16: =IF($X16="","",P16+ROW()/1000000) -> 1.6e-05 | W16: =IF($X16="","",K16+ROW()/1000000) -> 1.6e-05 | X16: =IFERROR(MATCH(ROW()-4,'Details Data Board'!$A$3:$A$6001,0)+1,"") -> 257 | Y16: =IF($X16="",0,ROUND(INDEX('Tracker&Invoice'!$G:$G,$X16)-J16,2)) -> 0
A17: =IF($X17="","",ROW()-4) -> 13 | B17: =IF($X17="","",INDEX('Tracker&Invoice'!$A:$A,$X17)) -> 0 | C17: =IF($X17="","",INDEX('Tracker&Invoice'!$B:$B,$X17)) -> INVOICE #13 | D17: =IF($X17="","",INDEX('Tracker&Invoice'!$E:$E,$X17)) -> 0 | E17: =IF($X17="","",INDEX('Tracker&Invoice'!$F:$F,$X17)) -> 0 | F17: =IF($X17="","",INDEX('Tracker&Invoice'!$C:$C,$X17)) -> 0 | G17: =IF($X17="","",INDEX('Tracker&Invoice'!$D:$D,$X17)) -> 0 | H17: =IF($X17="","",G17-F17) -> 0 | I17: =IF($X17="","",F17*E17) -> 0 | J17: =IF($X17="","",G17*E17) -> 0 | K17: =IF($X17="","",J17-I17) -> 0 | L17: =IF($X17="","",SUMIF('Details Data Board'!$C$3:$C$6001,B17,'Details Data Board'!$I$3:$I$6001)) -> 0 | M17: =IF($X17="","",IF(J17=0,0,L17/J17)) -> 0 | N17: =IF($X17="","",M17*G17) -> 0 | O17: =IF($X17="","",G17-N17) -> 0 | P17: =IF($X17="","",J17-L17) -> 0 | Q17: =IF($X17="","",IF(J17=0,0,P17/J17)) -> 0 | R17: =IF($X17="","",IF(INT(O17)=O17,TEXT(O17,"#,##0"),TEXT(O17,"#,##0.00"))&" "&D17&" | "&TEXT(P17,"#,##0")&" ريال | "&TEXT(Q17,"0.0%")) -> 0 0 | 0 ريال | 0.0% | S17: =IF($X17="","",IF(L17<=0,"لم يبدأ",IF(P17<-0.5,"تجاوز 100% - راجع",IF(P17<=0.5,"مكتمل","جاري")))) -> لم يبدأ | T17: =IF($X17="","",IF(AND(F17=0,G17>0),"جديد بأمر التغيير",IF(AND(G17=0,F17>0),"ملغي",IF(G17>F17,"زيادة",IF(G17<F17,"نقص","بدون تغيير"))))) -> بدون تغيير | U17: =IF($X17="","",IFERROR(LEFT(B17,FIND("-",B17)-1),B17)) -> 0 | V17: =IF($X17="","",P17+ROW()/1000000) -> 1.7e-05 | W17: =IF($X17="","",K17+ROW()/1000000) -> 1.7e-05 | X17: =IFERROR(MATCH(ROW()-4,'Details Data Board'!$A$3:$A$6001,0)+1,"") -> 279 | Y17: =IF($X17="",0,ROUND(INDEX('Tracker&Invoice'!$G:$G,$X17)-J17,2)) -> 0
A18: =IF($X18="","",ROW()-4) -> 14 | B18: =IF($X18="","",INDEX('Tracker&Invoice'!$A:$A,$X18)) -> 0 | C18: =IF($X18="","",INDEX('Tracker&Invoice'!$B:$B,$X18)) -> INVOICE #14 | D18: =IF($X18="","",INDEX('Tracker&Invoice'!$E:$E,$X18)) -> 0 | E18: =IF($X18="","",INDEX('Tracker&Invoice'!$F:$F,$X18)) -> 0 | F18: =IF($X18="","",INDEX('Tracker&Invoice'!$C:$C,$X18)) -> 0 | G18: =IF($X18="","",INDEX('Tracker&Invoice'!$D:$D,$X18)) -> 0 | H18: =IF($X18="","",G18-F18) -> 0 | I18: =IF($X18="","",F18*E18) -> 0 | J18: =IF($X18="","",G18*E18) -> 0 | K18: =IF($X18="","",J18-I18) -> 0 | L18: =IF($X18="","",SUMIF('Details Data Board'!$C$3:$C$6001,B18,'Details Data Board'!$I$3:$I$6001)) -> 0 | M18: =IF($X18="","",IF(J18=0,0,L18/J18)) -> 0 | N18: =IF($X18="","",M18*G18) -> 0 | O18: =IF($X18="","",G18-N18) -> 0 | P18: =IF($X18="","",J18-L18) -> 0 | Q18: =IF($X18="","",IF(J18=0,0,P18/J18)) -> 0 | R18: =IF($X18="","",IF(INT(O18)=O18,TEXT(O18,"#,##0"),TEXT(O18,"#,##0.00"))&" "&D18&" | "&TEXT(P18,"#,##0")&" ريال | "&TEXT(Q18,"0.0%")) -> 0 0 | 0 ريال | 0.0% | S18: =IF($X18="","",IF(L18<=0,"لم يبدأ",IF(P18<-0.5,"تجاوز 100% - راجع",IF(P18<=0.5,"مكتمل","جاري")))) -> لم يبدأ | T18: =IF($X18="","",IF(AND(F18=0,G18>0),"جديد بأمر التغيير",IF(AND(G18=0,F18>0),"ملغي",IF(G18>F18,"زيادة",IF(G18<F18,"نقص","بدون تغيير"))))) -> بدون تغيير | U18: =IF($X18="","",IFERROR(LEFT(B18,FIND("-",B18)-1),B18)) -> 0 | V18: =IF($X18="","",P18+ROW()/1000000) -> 1.8e-05 | W18: =IF($X18="","",K18+ROW()/1000000) -> 1.8e-05 | X18: =IFERROR(MATCH(ROW()-4,'Details Data Board'!$A$3:$A$6001,0)+1,"") -> 301 | Y18: =IF($X18="",0,ROUND(INDEX('Tracker&Invoice'!$G:$G,$X18)-J18,2)) -> 0
A19: =IF($X19="","",ROW()-4) -> 15 | B19: =IF($X19="","",INDEX('Tracker&Invoice'!$A:$A,$X19)) -> 0 | C19: =IF($X19="","",INDEX('Tracker&Invoice'!$B:$B,$X19)) -> INVOICE #14 | D19: =IF($X19="","",INDEX('Tracker&Invoice'!$E:$E,$X19)) -> 0 | E19: =IF($X19="","",INDEX('Tracker&Invoice'!$F:$F,$X19)) -> 0 | F19: =IF($X19="","",INDEX('Tracker&Invoice'!$C:$C,$X19)) -> 0 | G19: =IF($X19="","",INDEX('Tracker&Invoice'!$D:$D,$X19)) -> 0 | H19: =IF($X19="","",G19-F19) -> 0 | I19: =IF($X19="","",F19*E19) -> 0 | J19: =IF($X19="","",G19*E19) -> 0 | K19: =IF($X19="","",J19-I19) -> 0 | L19: =IF($X19="","",SUMIF('Details Data Board'!$C$3:$C$6001,B19,'Details Data Board'!$I$3:$I$6001)) -> 0 | M19: =IF($X19="","",IF(J19=0,0,L19/J19)) -> 0 | N19: =IF($X19="","",M19*G19) -> 0 | O19: =IF($X19="","",G19-N19) -> 0 | P19: =IF($X19="","",J19-L19) -> 0 | Q19: =IF($X19="","",IF(J19=0,0,P19/J19)) -> 0 | R19: =IF($X19="","",IF(INT(O19)=O19,TEXT(O19,"#,##0"),TEXT(O19,"#,##0.00"))&" "&D19&" | "&TEXT(P19,"#,##0")&" ريال | "&TEXT(Q19,"0.0%")) -> 0 0 | 0 ريال | 0.0% | S19: =IF($X19="","",IF(L19<=0,"لم يبدأ",IF(P19<-0.5,"تجاوز 100% - راجع",IF(P19<=0.5,"مكتمل","جاري")))) -> لم يبدأ | T19: =IF($X19="","",IF(AND(F19=0,G19>0),"جديد بأمر التغيير",IF(AND(G19=0,F19>0),"ملغي",IF(G19>F19,"زيادة",IF(G19<F19,"نقص","بدون تغيير"))))) -> بدون تغيير | U19: =IF($X19="","",IFERROR(LEFT(B19,FIND("-",B19)-1),B19)) -> 0 | V19: =IF($X19="","",P19+ROW()/1000000) -> 1.9e-05 | W19: =IF($X19="","",K19+ROW()/1000000) -> 1.9e-05 | X19: =IFERROR(MATCH(ROW()-4,'Details Data Board'!$A$3:$A$6001,0)+1,"") -> 323 | Y19: =IF($X19="",0,ROUND(INDEX('Tracker&Invoice'!$G:$G,$X19)-J19,2)) -> 0
A20: =IF($X20="","",ROW()-4) -> 16 | B20: =IF($X20="","",INDEX('Tracker&Invoice'!$A:$A,$X20)) -> 0 | C20: =IF($X20="","",INDEX('Tracker&Invoice'!$B:$B,$X20)) -> INVOICE #14 | D20: =IF($X20="","",INDEX('Tracker&Invoice'!$E:$E,$X20)) -> 0 | E20: =IF($X20="","",INDEX('Tracker&Invoice'!$F:$F,$X20)) -> 0 | F20: =IF($X20="","",INDEX('Tracker&Invoice'!$C:$C,$X20)) -> 0 | G20: =IF($X20="","",INDEX('Tracker&Invoice'!$D:$D,$X20)) -> 0 | H20: =IF($X20="","",G20-F20) -> 0 | I20: =IF($X20="","",F20*E20) -> 0 | J20: =IF($X20="","",G20*E20) -> 0 | K20: =IF($X20="","",J20-I20) -> 0 | L20: =IF($X20="","",SUMIF('Details Data Board'!$C$3:$C$6001,B20,'Details Data Board'!$I$3:$I$6001)) -> 0 | M20: =IF($X20="","",IF(J20=0,0,L20/J20)) -> 0 | N20: =IF($X20="","",M20*G20) -> 0 | O20: =IF($X20="","",G20-N20) -> 0 | P20: =IF($X20="","",J20-L20) -> 0 | Q20: =IF($X20="","",IF(J20=0,0,P20/J20)) -> 0 | R20: =IF($X20="","",IF(INT(O20)=O20,TEXT(O20,"#,##0"),TEXT(O20,"#,##0.00"))&" "&D20&" | "&TEXT(P20,"#,##0")&" ريال | "&TEXT(Q20,"0.0%")) -> 0 0 | 0 ريال | 0.0% | S20: =IF($X20="","",IF(L20<=0,"لم يبدأ",IF(P20<-0.5,"تجاوز 100% - راجع",IF(P20<=0.5,"مكتمل","جاري")))) -> لم يبدأ | T20: =IF($X20="","",IF(AND(F20=0,G20>0),"جديد بأمر التغيير",IF(AND(G20=0,F20>0),"ملغي",IF(G20>F20,"زيادة",IF(G20<F20,"نقص","بدون تغيير"))))) -> بدون تغيير | U20: =IF($X20="","",IFERROR(LEFT(B20,FIND("-",B20)-1),B20)) -> 0 | V20: =IF($X20="","",P20+ROW()/1000000) -> 2e-05 | W20: =IF($X20="","",K20+ROW()/1000000) -> 2e-05 | X20: =IFERROR(MATCH(ROW()-4,'Details Data Board'!$A$3:$A$6001,0)+1,"") -> 345 | Y20: =IF($X20="",0,ROUND(INDEX('Tracker&Invoice'!$G:$G,$X20)-J20,2)) -> 0
A21: =IF($X21="","",ROW()-4) -> 17 | B21: =IF($X21="","",INDEX('Tracker&Invoice'!$A:$A,$X21)) -> 0 | C21: =IF($X21="","",INDEX('Tracker&Invoice'!$B:$B,$X21)) -> INVOICE #26 | D21: =IF($X21="","",INDEX('Tracker&Invoice'!$E:$E,$X21)) -> 0 | E21: =IF($X21="","",INDEX('Tracker&Invoice'!$F:$F,$X21)) -> 0 | F21: =IF($X21="","",INDEX('Tracker&Invoice'!$C:$C,$X21)) -> 0 | G21: =IF($X21="","",INDEX('Tracker&Invoice'!$D:$D,$X21)) -> 0 | H21: =IF($X21="","",G21-F21) -> 0 | I21: =IF($X21="","",F21*E21) -> 0 | J21: =IF($X21="","",G21*E21) -> 0 | K21: =IF($X21="","",J21-I21) -> 0 | L21: =IF($X21="","",SUMIF('Details Data Board'!$C$3:$C$6001,B21,'Details Data Board'!$I$3:$I$6001)) -> 0 | M21: =IF($X21="","",IF(J21=0,0,L21/J21)) -> 0 | N21: =IF($X21="","",M21*G21) -> 0 | O21: =IF($X21="","",G21-N21) -> 0 | P21: =IF($X21="","",J21-L21) -> 0 | Q21: =IF($X21="","",IF(J21=0,0,P21/J21)) -> 0 | R21: =IF($X21="","",IF(INT(O21)=O21,TEXT(O21,"#,##0"),TEXT(O21,"#,##0.00"))&" "&D21&" | "&TEXT(P21,"#,##0")&" ريال | "&TEXT(Q21,"0.0%")) -> 0 0 | 0 ريال | 0.0% | S21: =IF($X21="","",IF(L21<=0,"لم يبدأ",IF(P21<-0.5,"تجاوز 100% - راجع",IF(P21<=0.5,"مكتمل","جاري")))) -> لم يبدأ | T21: =IF($X21="","",IF(AND(F21=0,G21>0),"جديد بأمر التغيير",IF(AND(G21=0,F21>0),"ملغي",IF(G21>F21,"زيادة",IF(G21<F21,"نقص","بدون تغيير"))))) -> بدون تغيير | U21: =IF($X21="","",IFERROR(LEFT(B21,FIND("-",B21)-1),B21)) -> 0 | V21: =IF($X21="","",P21+ROW()/1000000) -> 2.1e-05 | W21: =IF($X21="","",K21+ROW()/1000000) -> 2.1e-05 | X21: =IFERROR(MATCH(ROW()-4,'Details Data Board'!$A$3:$A$6001,0)+1,"") -> 367 | Y21: =IF($X21="",0,ROUND(INDEX('Tracker&Invoice'!$G:$G,$X21)-J21,2)) -> 0
A22: =IF($X22="","",ROW()-4) -> 18 | B22: =IF($X22="","",INDEX('Tracker&Invoice'!$A:$A,$X22)) -> 0 | C22: =IF($X22="","",INDEX('Tracker&Invoice'!$B:$B,$X22)) -> INVOICE #16 | D22: =IF($X22="","",INDEX('Tracker&Invoice'!$E:$E,$X22)) -> 0 | E22: =IF($X22="","",INDEX('Tracker&Invoice'!$F:$F,$X22)) -> 0 | F22: =IF($X22="","",INDEX('Tracker&Invoice'!$C:$C,$X22)) -> 0 | G22: =IF($X22="","",INDEX('Tracker&Invoice'!$D:$D,$X22)) -> 0 | H22: =IF($X22="","",G22-F22) -> 0 | I22: =IF($X22="","",F22*E22) -> 0 | J22: =IF($X22="","",G22*E22) -> 0 | K22: =IF($X22="","",J22-I22) -> 0 | L22: =IF($X22="","",SUMIF('Details Data Board'!$C$3:$C$6001,B22,'Details Data Board'!$I$3:$I$6001)) -> 0 | M22: =IF($X22="","",IF(J22=0,0,L22/J22)) -> 0 | N22: =IF($X22="","",M22*G22) -> 0 | O22: =IF($X22="","",G22-N22) -> 0 | P22: =IF($X22="","",J22-L22) -> 0 | Q22: =IF($X22="","",IF(J22=0,0,P22/J22)) -> 0 | R22: =IF($X22="","",IF(INT(O22)=O22,TEXT(O22,"#,##0"),TEXT(O22,"#,##0.00"))&" "&D22&" | "&TEXT(P22,"#,##0")&" ريال | "&TEXT(Q22,"0.0%")) -> 0 0 | 0 ريال | 0.0% | S22: =IF($X22="","",IF(L22<=0,"لم يبدأ",IF(P22<-0.5,"تجاوز 100% - راجع",IF(P22<=0.5,"مكتمل","جاري")))) -> لم يبدأ | T22: =IF($X22="","",IF(AND(F22=0,G22>0),"جديد بأمر التغيير",IF(AND(G22=0,F22>0),"ملغي",IF(G22>F22,"زيادة",IF(G22<F22,"نقص","بدون تغيير"))))) -> بدون تغيير | U22: =IF($X22="","",IFERROR(LEFT(B22,FIND("-",B22)-1),B22)) -> 0 | V22: =IF($X22="","",P22+ROW()/1000000) -> 2.2e-05 | W22: =IF($X22="","",K22+ROW()/1000000) -> 2.2e-05 | X22: =IFERROR(MATCH(ROW()-4,'Details Data Board'!$A$3:$A$6001,0)+1,"") -> 389 | Y22: =IF($X22="",0,ROUND(INDEX('Tracker&Invoice'!$G:$G,$X22)-J22,2)) -> 0
A23: =IF($X23="","",ROW()-4) -> 19 | B23: =IF($X23="","",INDEX('Tracker&Invoice'!$A:$A,$X23)) -> 0 | C23: =IF($X23="","",INDEX('Tracker&Invoice'!$B:$B,$X23)) -> INVOICE #13 | D23: =IF($X23="","",INDEX('Tracker&Invoice'!$E:$E,$X23)) -> 0 | E23: =IF($X23="","",INDEX('Tracker&Invoice'!$F:$F,$X23)) -> 0 | F23: =IF($X23="","",INDEX('Tracker&Invoice'!$C:$C,$X23)) -> 0 | G23: =IF($X23="","",INDEX('Tracker&Invoice'!$D:$D,$X23)) -> 0 | H23: =IF($X23="","",G23-F23) -> 0 | I23: =IF($X23="","",F23*E23) -> 0 | J23: =IF($X23="","",G23*E23) -> 0 | K23: =IF($X23="","",J23-I23) -> 0 | L23: =IF($X23="","",SUMIF('Details Data Board'!$C$3:$C$6001,B23,'Details Data Board'!$I$3:$I$6001)) -> 0 | M23: =IF($X23="","",IF(J23=0,0,L23/J23)) -> 0 | N23: =IF($X23="","",M23*G23) -> 0 | O23: =IF($X23="","",G23-N23) -> 0 | P23: =IF($X23="","",J23-L23) -> 0 | Q23: =IF($X23="","",IF(J23=0,0,P23/J23)) -> 0 | R23: =IF($X23="","",IF(INT(O23)=O23,TEXT(O23,"#,##0"),TEXT(O23,"#,##0.00"))&" "&D23&" | "&TEXT(P23,"#,##0")&" ريال | "&TEXT(Q23,"0.0%")) -> 0 0 | 0 ريال | 0.0% | S23: =IF($X23="","",IF(L23<=0,"لم يبدأ",IF(P23<-0.5,"تجاوز 100% - راجع",IF(P23<=0.5,"مكتمل","جاري")))) -> لم يبدأ | T23: =IF($X23="","",IF(AND(F23=0,G23>0),"جديد بأمر التغيير",IF(AND(G23=0,F23>0),"ملغي",IF(G23>F23,"زيادة",IF(G23<F23,"نقص","بدون تغيير"))))) -> بدون تغيير | U23: =IF($X23="","",IFERROR(LEFT(B23,FIND("-",B23)-1),B23)) -> 0 | V23: =IF($X23="","",P23+ROW()/1000000) -> 2.3e-05 | W23: =IF($X23="","",K23+ROW()/1000000) -> 2.3e-05 | X23: =IFERROR(MATCH(ROW()-4,'Details Data Board'!$A$3:$A$6001,0)+1,"") -> 411 | Y23: =IF($X23="",0,ROUND(INDEX('Tracker&Invoice'!$G:$G,$X23)-J23,2)) -> 0
... A354: =IF($X354="","",ROW()-4) | B354: =IF($X354="","",INDEX('Tracker&Invoice'!$A:$A,$X354)) | C354: =IF($X354="","",INDEX('Tracker&Invoice'!$B:$B,$X354)) | D354: =IF($X354="","",INDEX('Tracker&Invoice'!$E:$E,$X354)) | E354: =IF($X354="","",INDEX('Tracker&Invoice'!$F:$F,$X354)) | F354: =IF($X354="","",INDEX('Tracker&Invoice'!$C:$C,$X354)) | G354: =IF($X354="","",INDEX('Tracker&Invoice'!$D:$D,$X354)) | H354: =IF($X354="","",G354-F354) | I354: =IF($X354="","",F354*E354) | J354: =IF($X354="","",G354*E354) | K354: =IF($X354="","",J354-I354) | L354: =IF($X354="","",SUMIF('Details Data Board'!$C$3:$C$6001,B354,'Details Data Board'!$I$3:$I$6001)) | M354: =IF($X354="","",IF(J354=0,0,L354/J354)) | N354: =IF($X354="","",M354*G354) | O354: =IF($X354="","",G354-N354) | P354: =IF($X354="","",J354-L354) | Q354: =IF($X354="","",IF(J354=0,0,P354/J354)) | R354: =IF($X354="","",IF(INT(O354)=O354,TEXT(O354,"#,##0"),TEXT(O354,"#,##0.00"))&" "&D354&" | "&TEXT(P354,"#,##0")&" ريال | "&TEXT(Q354,"0.0%")) | S354: =IF($X354="","",IF(L354<=0,"لم يبدأ",IF(P354<-0.5,"تجاوز 100% - راجع",IF(P354<=0.5,"مكتمل","جاري")))) | T354: =IF($X354="","",IF(AND(F354=0,G354>0),"جديد بأمر التغيير",IF(AND(G354=0,F354>0),"ملغي",IF(G354>F354,"زيادة",IF(G354<F354,"نقص","بدون تغيير"))))) | U354: =IF($X354="","",IFERROR(LEFT(B354,FIND("-",B354)-1),B354)) | V354: =IF($X354="","",P354+ROW()/1000000) | W354: =IF($X354="","",K354+ROW()/1000000) | X354: =IFERROR(MATCH(ROW()-4,'Details Data Board'!$A$3:$A$6001,0)+1,"") | Y354: =IF($X354="",0,ROUND(INDEX('Tracker&Invoice'!$G:$G,$X354)-J354,2)) -> 0

Sheet Late&Supervision payment fee
A2: مراحل غرامة التأخير (حسب العقد)
A3: المرحلة | B3: نسبة الغرامة من التكلفة اليومية | C3: الحد الأدنى (يوم) | D3: % من مدة المشروع | E3: الحد التراكمي (يوم)
A4: المرحلة الأولى | B4: 0.25 | C4: 15 | D4: 0.1 | E4: =ROUND(MAX(C4,D4*'Summry Invoices'!B41),0) -> 84
A5: المرحلة الثانية | B5: 0.5 | C5: 30 | D5: 0.15 | E5: =ROUND(MAX(C5,D5*'Summry Invoices'!B41),0) -> 126 | G5: 46320 | H5: 0.49861111
A6: المرحلة الثالثة | B6: 1 | C6: — | D6: — | E6: ما بعد المرحلة الثانية
A10: حساب غرامة التأخير
A11: رقم المستخلص | B11: الفترة | D11: أيام التأخير في الفترة | E11: التأخير التراكمي قبله | F11: أيام بغرامة 25% | G11: أيام بغرامة 50% | H11: أيام بغرامة 100% | I11: غرامة 25% | J11: غرامة 50% | K11: غرامة 100% | L11: إجمالي غرامة التأخير
A12: الإجمالي | D12: =SUM(D13:D21) -> 132 | F12: =SUM(F13:F21) -> 84 | G12: =SUM(G13:G21) -> 42 | H12: =SUM(H13:H21) -> 6 | I12: =SUM(I13:I21) -> #VALUE! | J12: =SUM(J13:J21) -> #VALUE! | K12: =SUM(K13:K21) -> #VALUE! | L12: =SUM(L13:L21) -> #VALUE!
